#0 building with "default" instance using docker driver

#1 [internal] load .dockerignore
#1 transferring context: 2B done
#1 DONE 0.0s

#2 [internal] load build definition from Dockerfile
#2 transferring dockerfile: 503B done
#2 DONE 0.1s

#3 [auth] library/python:pull token for registry-1.docker.io
#3 DONE 0.0s

#4 [internal] load metadata for docker.io/library/python:3.11.2
#4 DONE 2.1s

#5 [1/4] FROM docker.io/library/python:3.11.2@sha256:5329e75033c4446dc92d702cf8ebbeb63e549d9b83076a776f6753e10817fc3c
#5 DONE 0.0s

#6 [internal] load build context
#6 transferring context: 78B done
#6 DONE 0.0s

#7 [2/4] WORKDIR /app
#7 CACHED

#8 [3/4] COPY CSV_Combiner_v4.5.py requirements.txt /app/
#8 CACHED

#9 [4/4] RUN pip install --no-cache-dir -r requirements.txt
#9 2.954 Collecting pandas==1.3.3
#9 3.372   Downloading pandas-1.3.3.tar.gz (4.7 MB)
#9 282.2      ━━━━━━━━━━━━━━━━━━━━━━━━━━━━━━━━━━       4.0/4.7 MB 7.4 kB/s eta 0:01:33
#9 282.2 ERROR: Exception:
#9 282.2 Traceback (most recent call last):
#9 282.2   File "/usr/local/lib/python3.11/site-packages/pip/_vendor/urllib3/response.py", line 437, in _error_catcher
#9 282.2     yield
#9 282.2   File "/usr/local/lib/python3.11/site-packages/pip/_vendor/urllib3/response.py", line 560, in read
#9 282.2     data = self._fp_read(amt) if not fp_closed else b""
#9 282.2            ^^^^^^^^^^^^^^^^^^
#9 282.2   File "/usr/local/lib/python3.11/site-packages/pip/_vendor/urllib3/response.py", line 526, in _fp_read
#9 282.2     return self._fp.read(amt) if amt is not None else self._fp.read()
#9 282.2            ^^^^^^^^^^^^^^^^^^
#9 282.2   File "/usr/local/lib/python3.11/http/client.py", line 465, in read
#9 282.2     s = self.fp.read(amt)
#9 282.2         ^^^^^^^^^^^^^^^^^
#9 282.2   File "/usr/local/lib/python3.11/socket.py", line 706, in readinto
#9 282.2     return self._sock.recv_into(b)
#9 282.2            ^^^^^^^^^^^^^^^^^^^^^^^
#9 282.2   File "/usr/local/lib/python3.11/ssl.py", line 1278, in recv_into
#9 282.2     return self.read(nbytes, buffer)
#9 282.2            ^^^^^^^^^^^^^^^^^^^^^^^^^
#9 282.2   File "/usr/local/lib/python3.11/ssl.py", line 1134, in read
#9 282.2     return self._sslobj.read(len, buffer)
#9 282.2            ^^^^^^^^^^^^^^^^^^^^^^^^^^^^^^
#9 282.2 TimeoutError: The read operation timed out
#9 282.2 
#9 282.2 During handling of the above exception, another exception occurred:
#9 282.2 
#9 282.2 Traceback (most recent call last):
#9 282.2   File "/usr/local/lib/python3.11/site-packages/pip/_internal/cli/base_command.py", line 160, in exc_logging_wrapper
#9 282.2     status = run_func(*args)
#9 282.2              ^^^^^^^^^^^^^^^
#9 282.2   File "/usr/local/lib/python3.11/site-packages/pip/_internal/cli/req_command.py", line 247, in wrapper
#9 282.2     return func(self, options, args)
#9 282.2            ^^^^^^^^^^^^^^^^^^^^^^^^^
#9 282.2   File "/usr/local/lib/python3.11/site-packages/pip/_internal/commands/install.py", line 400, in run
#9 282.2     requirement_set = resolver.resolve(
#9 282.2                       ^^^^^^^^^^^^^^^^^
#9 282.2   File "/usr/local/lib/python3.11/site-packages/pip/_internal/resolution/resolvelib/resolver.py", line 92, in resolve
#9 282.2     result = self._result = resolver.resolve(
#9 282.2                             ^^^^^^^^^^^^^^^^^
#9 282.2   File "/usr/local/lib/python3.11/site-packages/pip/_vendor/resolvelib/resolvers.py", line 481, in resolve
#9 282.2     state = resolution.resolve(requirements, max_rounds=max_rounds)
#9 282.2             ^^^^^^^^^^^^^^^^^^^^^^^^^^^^^^^^^^^^^^^^^^^^^^^^^^^^^^^
#9 282.2   File "/usr/local/lib/python3.11/site-packages/pip/_vendor/resolvelib/resolvers.py", line 348, in resolve
#9 282.2     self._add_to_criteria(self.state.criteria, r, parent=None)
#9 282.2   File "/usr/local/lib/python3.11/site-packages/pip/_vendor/resolvelib/resolvers.py", line 172, in _add_to_criteria
#9 282.2     if not criterion.candidates:
#9 282.2   File "/usr/local/lib/python3.11/site-packages/pip/_vendor/resolvelib/structs.py", line 151, in __bool__
#9 282.2     return bool(self._sequence)
#9 282.2            ^^^^^^^^^^^^^^^^^^^^
#9 282.2   File "/usr/local/lib/python3.11/site-packages/pip/_internal/resolution/resolvelib/found_candidates.py", line 155, in __bool__
#9 282.2     return any(self)
#9 282.2            ^^^^^^^^^
#9 282.2   File "/usr/local/lib/python3.11/site-packages/pip/_internal/resolution/resolvelib/found_candidates.py", line 143, in <genexpr>
#9 282.2     return (c for c in iterator if id(c) not in self._incompatible_ids)
#9 282.2            ^^^^^^^^^^^^^^^^^^^^^^^^^^^^^^^^^^^^^^^^^^^^^^^^^^^^^^^^^^^^
#9 282.2   File "/usr/local/lib/python3.11/site-packages/pip/_internal/resolution/resolvelib/found_candidates.py", line 47, in _iter_built
#9 282.2     candidate = func()
#9 282.2                 ^^^^^^
#9 282.2   File "/usr/local/lib/python3.11/site-packages/pip/_internal/resolution/resolvelib/factory.py", line 206, in _make_candidate_from_link
#9 282.2     self._link_candidate_cache[link] = LinkCandidate(
#9 282.2                                        ^^^^^^^^^^^^^^
#9 282.2   File "/usr/local/lib/python3.11/site-packages/pip/_internal/resolution/resolvelib/candidates.py", line 297, in __init__
#9 282.2     super().__init__(
#9 282.2   File "/usr/local/lib/python3.11/site-packages/pip/_internal/resolution/resolvelib/candidates.py", line 162, in __init__
#9 282.2     self.dist = self._prepare()
#9 282.2                 ^^^^^^^^^^^^^^^
#9 282.2   File "/usr/local/lib/python3.11/site-packages/pip/_internal/resolution/resolvelib/candidates.py", line 231, in _prepare
#9 282.2     dist = self._prepare_distribution()
#9 282.2            ^^^^^^^^^^^^^^^^^^^^^^^^^^^^
#9 282.2   File "/usr/local/lib/python3.11/site-packages/pip/_internal/resolution/resolvelib/candidates.py", line 308, in _prepare_distribution
#9 282.2     return preparer.prepare_linked_requirement(self._ireq, parallel_builds=True)
#9 282.2            ^^^^^^^^^^^^^^^^^^^^^^^^^^^^^^^^^^^^^^^^^^^^^^^^^^^^^^^^^^^^^^^^^^^^^
#9 282.2   File "/usr/local/lib/python3.11/site-packages/pip/_internal/operations/prepare.py", line 491, in prepare_linked_requirement
#9 282.2     return self._prepare_linked_requirement(req, parallel_builds)
#9 282.2            ^^^^^^^^^^^^^^^^^^^^^^^^^^^^^^^^^^^^^^^^^^^^^^^^^^^^^^
#9 282.2   File "/usr/local/lib/python3.11/site-packages/pip/_internal/operations/prepare.py", line 536, in _prepare_linked_requirement
#9 282.2     local_file = unpack_url(
#9 282.2                  ^^^^^^^^^^^
#9 282.2   File "/usr/local/lib/python3.11/site-packages/pip/_internal/operations/prepare.py", line 166, in unpack_url
#9 282.2     file = get_http_url(
#9 282.2            ^^^^^^^^^^^^^
#9 282.2   File "/usr/local/lib/python3.11/site-packages/pip/_internal/operations/prepare.py", line 107, in get_http_url
#9 282.2     from_path, content_type = download(link, temp_dir.path)
#9 282.2                               ^^^^^^^^^^^^^^^^^^^^^^^^^^^^^
#9 282.2   File "/usr/local/lib/python3.11/site-packages/pip/_internal/network/download.py", line 147, in __call__
#9 282.2     for chunk in chunks:
#9 282.2   File "/usr/local/lib/python3.11/site-packages/pip/_internal/cli/progress_bars.py", line 53, in _rich_progress_bar
#9 282.2     for chunk in iterable:
#9 282.2   File "/usr/local/lib/python3.11/site-packages/pip/_internal/network/utils.py", line 63, in response_chunks
#9 282.2     for chunk in response.raw.stream(
#9 282.2   File "/usr/local/lib/python3.11/site-packages/pip/_vendor/urllib3/response.py", line 621, in stream
#9 282.2     data = self.read(amt=amt, decode_content=decode_content)
#9 282.2            ^^^^^^^^^^^^^^^^^^^^^^^^^^^^^^^^^^^^^^^^^^^^^^^^^
#9 282.2   File "/usr/local/lib/python3.11/site-packages/pip/_vendor/urllib3/response.py", line 559, in read
#9 282.2     with self._error_catcher():
#9 282.2   File "/usr/local/lib/python3.11/contextlib.py", line 155, in __exit__
#9 282.2     self.gen.throw(typ, value, traceback)
#9 282.2   File "/usr/local/lib/python3.11/site-packages/pip/_vendor/urllib3/response.py", line 442, in _error_catcher
#9 282.2     raise ReadTimeoutError(self._pool, None, "Read timed out.")
#9 282.2 pip._vendor.urllib3.exceptions.ReadTimeoutError: HTTPSConnectionPool(host='files.pythonhosted.org', port=443): Read timed out.
#9 282.5 
#9 282.5 [notice] A new release of pip available: 22.3.1 -> 23.3.2
#9 282.5 [notice] To update, run: pip install --upgrade pip
#9 ERROR: process "/bin/sh -c pip install --no-cache-dir -r requirements.txt" did not complete successfully: exit code: 2
------
 > [4/4] RUN pip install --no-cache-dir -r requirements.txt:
282.2   File "/usr/local/lib/python3.11/site-packages/pip/_vendor/urllib3/response.py", line 559, in read
282.2     with self._error_catcher():
282.2   File "/usr/local/lib/python3.11/contextlib.py", line 155, in __exit__
282.2     self.gen.throw(typ, value, traceback)
282.2   File "/usr/local/lib/python3.11/site-packages/pip/_vendor/urllib3/response.py", line 442, in _error_catcher
282.2     raise ReadTimeoutError(self._pool, None, "Read timed out.")
282.2 pip._vendor.urllib3.exceptions.ReadTimeoutError: HTTPSConnectionPool(host='files.pythonhosted.org', port=443): Read timed out.
282.5 
282.5 [notice] A new release of pip available: 22.3.1 -> 23.3.2
282.5 [notice] To update, run: pip install --upgrade pip
------
Dockerfile:11
--------------------
   9 |     
  10 |     # Install any dependencies specified in requirements.txt
  11 | >>> RUN pip install --no-cache-dir -r requirements.txt
  12 |     
  13 |     # Specify the command to run your application
--------------------
ERROR: failed to solve: process "/bin/sh -c pip install --no-cache-dir -r requirements.txt" did not complete successfully: exit code: 2
